Workbook

Sheet Dashboard
B2: 🍴 Zomato Restaurants Analysis | Q2: FILTERS (use the dropdowns)
Q3: Country | T3: All
Q4: City | T4: All
Q5: Choose "All" to remove a filter. City must belong to chosen country.
B7: Total Restaurants | F7: Total Countries | J7: Total Cities | N7: Total Cuisines | R7: Average Rating | V7: Average Cost
B8: =Calc!K50 -> 9551 | F8: =Calc!K51 -> 15 | J8: =Calc!K52 -> 141 | N8: =Calc!K53 -> 1826 | R8: =Calc!K54 -> 2.8912679 | V8: =Calc!K55 -> 10.000223
B12: Top-5 Cuisines by Votes | H12: Top-5 Restaurants by Average Cost of Two in USD | N12: Percentage of Restaurants based on Table_booking Availability | T12: Percentage of Restaurants based on Online_delivery Availability
B29: Restaurants Categorized by Average Cost of Two in USD | N29: Restaurants by Rating Range

Sheet Data
A1: RestaurantID | B1: RestaurantName | C1: CountryCode | D1: City | E1: Address | F1: Locality | G1: LocalityVerbose | H1: Cuisines | I1: Currency | J1: Has_Table_booking | K1: Has_Online_delivery | L1: Is_delivering_now | M1: Switch_to_order_menu | N1: Price_range | O1: Votes | P1: Average_Cost_for_two | Q1: Rating | R1: Country | S1: USD_Rate | T1: Avg_Cost_USD | U1: Cost_Band | V1: In_Filter | W1: Rank_Key
A2: 6317637 | B2: Le Petit Souffle | C2: 162 | D2: Makati City | E2: Third Floor| Century City Mall| Kalayaan Avenue| Poblacion| Makati City | F2: Century City Mall| Poblacion| Makati City | G2: Century City Mall| Poblacion| Makati City| Makati City | H2: French, Japanese, Desserts | I2: Botswana Pula(P) | J2: Yes | K2: No | L2: No | M2: No | N2: 3 | O2: 314 | P2: 1100 | Q2: 4.8 | R2: =INDEX(Lookup!$B$4:$B$18,MATCH(C2,Lookup!$A$4:$A$18,0)) -> Philippines | S2: =INDEX(Lookup!$D$4:$D$18,MATCH(C2,Lookup!$A$4:$A$18,0)) -> 0.073 | T2: =ROUND(P2*S2,2) -> 80.3 | U2: =IF(T2<=10,1,IF(T2<=20,2,IF(T2<=30,3,IF(T2<=40,4,IF(T2<=50,5,IF(T2<=100,6,IF(T2<=250,7,8))))))) -> 6 | V2: =IF(AND(OR(Dashboard!$T$3="All",R2=Dashboard!$T$3),OR(Dashboard!$T$4="All",D2=Dashboard!$T$4)),1,0) -> 1 | W2: =IF(V2=1,T2+ROW()/10000000,0) -> 80.3
A3: 6304287 | B3: Izakaya Kikufuji | C3: 162 | D3: Makati City | E3: Little Tokyo| 2277 Chino Roces Avenue| Legaspi Village| Makati City | F3: Little Tokyo| Legaspi Village| Makati City | G3: Little Tokyo| Legaspi Village| Makati City| Makati City | H3: Japanese | I3: Botswana Pula(P) | J3: Yes | K3: No | L3: No | M3: No | N3: 3 | O3: 591 | P3: 1200 | Q3: 4.5 | R3: =INDEX(Lookup!$B$4:$B$18,MATCH(C3,Lookup!$A$4:$A$18,0)) -> Philippines | S3: =INDEX(Lookup!$D$4:$D$18,MATCH(C3,Lookup!$A$4:$A$18,0)) -> 0.073 | T3: =ROUND(P3*S3,2) -> 87.6 | U3: =IF(T3<=10,1,IF(T3<=20,2,IF(T3<=30,3,IF(T3<=40,4,IF(T3<=50,5,IF(T3<=100,6,IF(T3<=250,7,8))))))) -> 6 | V3: =IF(AND(OR(Dashboard!$T$3="All",R3=Dashboard!$T$3),OR(Dashboard!$T$4="All",D3=Dashboard!$T$4)),1,0) -> 1 | W3: =IF(V3=1,T3+ROW()/10000000,0) -> 87.6
A4: 6300002 | B4: Heat - Edsa Shangri-La | C4: 162 | D4: Mandaluyong City | E4: Edsa Shangri-La| 1 Garden Way| Ortigas| Mandaluyong City | F4: Edsa Shangri-La| Ortigas| Mandaluyong City | G4: Edsa Shangri-La| Ortigas| Mandaluyong City| Mandaluyong City | H4: Seafood, Asian, Filipino, Indian | I4: Botswana Pula(P) | J4: Yes | K4: No | L4: No | M4: No | N4: 4 | O4: 270 | P4: 4000 | Q4: 4.4 | R4: =INDEX(Lookup!$B$4:$B$18,MATCH(C4,Lookup!$A$4:$A$18,0)) -> Philippines | S4: =INDEX(Lookup!$D$4:$D$18,MATCH(C4,Lookup!$A$4:$A$18,0)) -> 0.073 | T4: =ROUND(P4*S4,2) -> 292 | U4: =IF(T4<=10,1,IF(T4<=20,2,IF(T4<=30,3,IF(T4<=40,4,IF(T4<=50,5,IF(T4<=100,6,IF(T4<=250,7,8))))))) -> 8 | V4: =IF(AND(OR(Dashboard!$T$3="All",R4=Dashboard!$T$3),OR(Dashboard!$T$4="All",D4=Dashboard!$T$4)),1,0) -> 1 | W4: =IF(V4=1,T4+ROW()/10000000,0) -> 292
A5: 6318506 | B5: Ooma | C5: 162 | D5: Mandaluyong City | E5: Third Floor| Mega Fashion Hall| SM Megamall| Ortigas| Mandaluyong City | F5: SM Megamall| Ortigas| Mandaluyong City | G5: SM Megamall| Ortigas| Mandaluyong City| Mandaluyong City | H5: Japanese, Sushi | I5: Botswana Pula(P) | J5: No | K5: No | L5: No | M5: No | N5: 4 | O5: 365 | P5: 1500 | Q5: 4.9 | R5: =INDEX(Lookup!$B$4:$B$18,MATCH(C5,Lookup!$A$4:$A$18,0)) -> Philippines | S5: =INDEX(Lookup!$D$4:$D$18,MATCH(C5,Lookup!$A$4:$A$18,0)) -> 0.073 | T5: =ROUND(P5*S5,2) -> 109.5 | U5: =IF(T5<=10,1,IF(T5<=20,2,IF(T5<=30,3,IF(T5<=40,4,IF(T5<=50,5,IF(T5<=100,6,IF(T5<=250,7,8))))))) -> 7 | V5: =IF(AND(OR(Dashboard!$T$3="All",R5=Dashboard!$T$3),OR(Dashboard!$T$4="All",D5=Dashboard!$T$4)),1,0) -> 1 | W5: =IF(V5=1,T5+ROW()/10000000,0) -> 109.5
A6: 6314302 | B6: Sambo Kojin | C6: 162 | D6: Mandaluyong City | E6: Third Floor| Mega Atrium| SM Megamall| Ortigas| Mandaluyong City | F6: SM Megamall| Ortigas| Mandaluyong City | G6: SM Megamall| Ortigas| Mandaluyong City| Mandaluyong City | H6: Japanese, Korean | I6: Botswana Pula(P) | J6: Yes | K6: No | L6: No | M6: No | N6: 4 | O6: 229 | P6: 1500 | Q6: 4.8 | R6: =INDEX(Lookup!$B$4:$B$18,MATCH(C6,Lookup!$A$4:$A$18,0)) -> Philippines | S6: =INDEX(Lookup!$D$4:$D$18,MATCH(C6,Lookup!$A$4:$A$18,0)) -> 0.073 | T6: =ROUND(P6*S6,2) -> 109.5 | U6: =IF(T6<=10,1,IF(T6<=20,2,IF(T6<=30,3,IF(T6<=40,4,IF(T6<=50,5,IF(T6<=100,6,IF(T6<=250,7,8))))))) -> 7 | V6: =IF(AND(OR(Dashboard!$T$3="All",R6=Dashboard!$T$3),OR(Dashboard!$T$4="All",D6=Dashboard!$T$4)),1,0) -> 1 | W6: =IF(V6=1,T6+ROW()/10000000,0) -> 109.5
A7: 18189371 | B7: Din Tai Fung | C7: 162 | D7: Mandaluyong City | E7: Ground Floor| Mega Fashion Hall| SM Megamall| Ortigas| Mandaluyong City | F7: SM Megamall| Ortigas| Mandaluyong City | G7: SM Megamall| Ortigas| Mandaluyong City| Mandaluyong City | H7: Chinese | I7: Botswana Pula(P) | J7: No | K7: No | L7: No | M7: No | N7: 3 | O7: 336 | P7: 1000 | Q7: 4.4 | R7: =INDEX(Lookup!$B$4:$B$18,MATCH(C7,Lookup!$A$4:$A$18,0)) -> Philippines | S7: =INDEX(Lookup!$D$4:$D$18,MATCH(C7,Lookup!$A$4:$A$18,0)) -> 0.073 | T7: =ROUND(P7*S7,2) -> 73 | U7: =IF(T7<=10,1,IF(T7<=20,2,IF(T7<=30,3,IF(T7<=40,4,IF(T7<=50,5,IF(T7<=100,6,IF(T7<=250,7,8))))))) -> 6 | V7: =IF(AND(OR(Dashboard!$T$3="All",R7=Dashboard!$T$3),OR(Dashboard!$T$4="All",D7=Dashboard!$T$4)),1,0) -> 1 | W7: =IF(V7=1,T7+ROW()/10000000,0) -> 73.000001
A8: 6300781 | B8: Buffet 101 | C8: 162 | D8: Pasay City | E8: Building K| SM By The Bay| Sunset Boulevard| Mall of Asia Complex (MOA)| Pasay City | F8: SM by the Bay| Mall of Asia Complex| Pasay City | G8: SM by the Bay| Mall of Asia Complex| Pasay City| Pasay City | H8: Asian, European | I8: Botswana Pula(P) | J8: Yes | K8: No | L8: No | M8: No | N8: 4 | O8: 520 | P8: 2000 | Q8: 4 | R8: =INDEX(Lookup!$B$4:$B$18,MATCH(C8,Lookup!$A$4:$A$18,0)) -> Philippines | S8: =INDEX(Lookup!$D$4:$D$18,MATCH(C8,Lookup!$A$4:$A$18,0)) -> 0.073 | T8: =ROUND(P8*S8,2) -> 146 | U8: =IF(T8<=10,1,IF(T8<=20,2,IF(T8<=30,3,IF(T8<=40,4,IF(T8<=50,5,IF(T8<=100,6,IF(T8<=250,7,8))))))) -> 7 | V8: =IF(AND(OR(Dashboard!$T$3="All",R8=Dashboard!$T$3),OR(Dashboard!$T$4="All",D8=Dashboard!$T$4)),1,0) -> 1 | W8: =IF(V8=1,T8+ROW()/10000000,0) -> 146
A9: 6301290 | B9: Vikings | C9: 162 | D9: Pasay City | E9: Building B| By The Bay| Seaside Boulevard| Mall of Asia Complex (MOA)| Pasay City | F9: SM by the Bay| Mall of Asia Complex| Pasay City | G9: SM by the Bay| Mall of Asia Complex| Pasay City| Pasay City | H9: Seafood, Filipino, Asian, European | I9: Botswana Pula(P) | J9: Yes | K9: No | L9: No | M9: No | N9: 4 | O9: 677 | P9: 2000 | Q9: 4.2 | R9: =INDEX(Lookup!$B$4:$B$18,MATCH(C9,Lookup!$A$4:$A$18,0)) -> Philippines | S9: =INDEX(Lookup!$D$4:$D$18,MATCH(C9,Lookup!$A$4:$A$18,0)) -> 0.073 | T9: =ROUND(P9*S9,2) -> 146 | U9: =IF(T9<=10,1,IF(T9<=20,2,IF(T9<=30,3,IF(T9<=40,4,IF(T9<=50,5,IF(T9<=100,6,IF(T9<=250,7,8))))))) -> 7 | V9: =IF(AND(OR(Dashboard!$T$3="All",R9=Dashboard!$T$3),OR(Dashboard!$T$4="All",D9=Dashboard!$T$4)),1,0) -> 1 | W9: =IF(V9=1,T9+ROW()/10000000,0) -> 146
A10: 6300010 | B10: Spiral - Sofitel Philippine Plaza Manila | C10: 162 | D10: Pasay City | E10: Plaza Level| Sofitel Philippine Plaza Manila| CCP Complex| Pasay City | F10: Sofitel Philippine Plaza Manila| Pasay City | G10: Sofitel Philippine Plaza Manila| Pasay City| Pasay City | H10: European, Asian, Indian | I10: Botswana Pula(P) | J10: Yes | K10: No | L10: No | M10: No | N10: 4 | O10: 621 | P10: 6000 | Q10: 4.9 | R10: =INDEX(Lookup!$B$4:$B$18,MATCH(C10,Lookup!$A$4:$A$18,0)) -> Philippines | S10: =INDEX(Lookup!$D$4:$D$18,MATCH(C10,Lookup!$A$4:$A$18,0)) -> 0.073 | T10: =ROUND(P10*S10,2) -> 438 | U10: =IF(T10<=10,1,IF(T10<=20,2,IF(T10<=30,3,IF(T10<=40,4,IF(T10<=50,5,IF(T10<=100,6,IF(T10<=250,7,8))))))) -> 8 | V10: =IF(AND(OR(Dashboard!$T$3="All",R10=Dashboard!$T$3),OR(Dashboard!$T$4="All",D10=Dashboard!$T$4)),1,0) -> 1 | W10: =IF(V10=1,T10+ROW()/10000000,0) -> 438
A11: 6314987 | B11: Locavore | C11: 162 | D11: Pasig City | E11: Brixton Technology Center| 10 Brixton Street| Kapitolyo| Pasig City | F11: Kapitolyo | G11: Kapitolyo| Pasig City | H11: Filipino | I11: Botswana Pula(P) | J11: Yes | K11: No | L11: No | M11: No | N11: 3 | O11: 532 | P11: 1100 | Q11: 4.8 | R11: =INDEX(Lookup!$B$4:$B$18,MATCH(C11,Lookup!$A$4:$A$18,0)) -> Philippines | S11: =INDEX(Lookup!$D$4:$D$18,MATCH(C11,Lookup!$A$4:$A$18,0)) -> 0.073 | T11: =ROUND(P11*S11,2) -> 80.3 | U11: =IF(T11<=10,1,IF(T11<=20,2,IF(T11<=30,3,IF(T11<=40,4,IF(T11<=50,5,IF(T11<=100,6,IF(T11<=250,7,8))))))) -> 6 | V11: =IF(AND(OR(Dashboard!$T$3="All",R11=Dashboard!$T$3),OR(Dashboard!$T$4="All",D11=Dashboard!$T$4)),1,0) -> 1 | W11: =IF(V11=1,T11+ROW()/10000000,0) -> 80.300001
A12: 6309903 | B12: Silantro Fil-Mex | C12: 162 | D12: Pasig City | E12: 75 East Capitol Drive| Kapitolyo| Pasig City | F12: Kapitolyo | G12: Kapitolyo| Pasig City | H12: Filipino, Mexican | I12: Botswana Pula(P) | J12: No | K12: No | L12: No | M12: No | N12: 3 | O12: 1070 | P12: 800 | Q12: 4.9 | R12: =INDEX(Lookup!$B$4:$B$18,MATCH(C12,Lookup!$A$4:$A$18,0)) -> Philippines | S12: =INDEX(Lookup!$D$4:$D$18,MATCH(C12,Lookup!$A$4:$A$18,0)) -> 0.073 | T12: =ROUND(P12*S12,2) -> 58.4 | U12: =IF(T12<=10,1,IF(T12<=20,2,IF(T12<=30,3,IF(T12<=40,4,IF(T12<=50,5,IF(T12<=100,6,IF(T12<=250,7,8))))))) -> 6 | V12: =IF(AND(OR(Dashboard!$T$3="All",R12=Dashboard!$T$3),OR(Dashboard!$T$4="All",D12=Dashboard!$T$4)),1,0) -> 1 | W12: =IF(V12=1,T12+ROW()/10000000,0) -> 58.400001
A13: 6309455 | B13: Mad Mark's Creamery & Good Eats | C13: 162 | D13: Pasig City | E13: 23 East Capitol Drive| Kapitolyo| Pasig City | F13: Kapitolyo | G13: Kapitolyo| Pasig City | H13: American, Ice Cream, Desserts | I13: Botswana Pula(P) | J13: Yes | K13: No | L13: No | M13: No | N13: 3 | O13: 488 | P13: 900 | Q13: 4.2 | R13: =INDEX(Lookup!$B$4:$B$18,MATCH(C13,Lookup!$A$4:$A$18,0)) -> Philippines | S13: =INDEX(Lookup!$D$4:$D$18,MATCH(C13,Lookup!$A$4:$A$18,0)) -> 0.073 | T13: =ROUND(P13*S13,2) -> 65.7 | U13: =IF(T13<=10,1,IF(T13<=20,2,IF(T13<=30,3,IF(T13<=40,4,IF(T13<=50,5,IF(T13<=100,6,IF(T13<=250,7,8))))))) -> 6 | V13: =IF(AND(OR(Dashboard!$T$3="All",R13=Dashboard!$T$3),OR(Dashboard!$T$4="All",D13=Dashboard!$T$4)),1,0) -> 1 | W13: =IF(V13=1,T13+ROW()/10000000,0) -> 65.700001
... A9552: 5927402 | B9552: Walter's Coffee Roastery | C9552: 208 | D9552: ?stanbul | E9552: Cafea?a Mahallesi| Bademalt? Sokak| No 21/B| Kad?k?y| ?stanbul | F9552: Moda | G9552: Moda| ?stanbul | H9552: Cafe | I9552: Turkish Lira(TL) | J9552: No | K9552: No | L9552: No | M9552: No | N9552: 2 | O9552: 591 | P9552: 55 | Q9552: 4 | R9552: =INDEX(Lookup!$B$4:$B$18,MATCH(C9552,Lookup!$A$4:$A$18,0)) -> Turkey | S9552: =INDEX(Lookup!$D$4:$D$18,MATCH(C9552,Lookup!$A$4:$A$18,0)) -> 0.023 | T9552: =ROUND(P9552*S9552,2) -> 1.27 | U9552: =IF(T9552<=10,1,IF(T9552<=20,2,IF(T9552<=30,3,IF(T9552<=40,4,IF(T9552<=50,5,IF(T9552<=100,6,IF(T9552<=250,7,8))))))) -> 1 | V9552: =IF(AND(OR(Dashboard!$T$3="All",R9552=Dashboard!$T$3),OR(Dashboard!$T$4="All",D9552=Dashboard!$T$4)),1,0) -> 1 | W9552: =IF(V9552=1,T9552+ROW()/10000000,0) -> 1.2709552

Sheet Calc
A1: Calculation sheet (feeds the dashboard charts). Do not edit.
F3: City dropdown list
A4: Cuisine | B4: Votes (filtered) | C4: Restaurants (filtered) | D4: Rank key | F4: All | G4: Restaurants (filtered) | I4: Rank | J4: Top-5 Cuisines by Votes | K4: Votes
A5: Afghani | B5: =SUMIFS(Data!$O$2:$O$9552,Data!$H$2:$H$9552,A5,Data!$V$2:$V$9552,1) -> 39 | C5: =COUNTIFS(Data!$H$2:$H$9552,A5,Data!$V$2:$V$9552,1) -> 4 | D5: =IF(C5>0,B5+ROW()/1000000,0) -> 39.000005 | F5: ?stanbul | G5: =COUNTIFS(Data!$D$2:$D$9552,F5,Data!$V$2:$V$9552,1) -> 14 | I5: 1 | J5: =IF(LARGE($D$5:$D$1830,I5)>0,INDEX($A$5:$A$1830,MATCH(LARGE($D$5:$D$1830,I5),$D$5:$D$1830,0)),"-") -> North Indian, Mughlai | K5: =IF(LARGE($D$5:$D$1830,I5)>0,INDEX($B$5:$B$1830,MATCH(LARGE($D$5:$D$1830,I5),$D$5:$D$1830,0)),0) -> 53747
A6: Afghani, Mughlai, Chinese | B6: =SUMIFS(Data!$O$2:$O$9552,Data!$H$2:$H$9552,A6,Data!$V$2:$V$9552,1) -> 2 | C6: =COUNTIFS(Data!$H$2:$H$9552,A6,Data!$V$2:$V$9552,1) -> 1 | D6: =IF(C6>0,B6+ROW()/1000000,0) -> 2.000006 | F6: Abu Dhabi | G6: =COUNTIFS(Data!$D$2:$D$9552,F6,Data!$V$2:$V$9552,1) -> 20 | I6: 2 | J6: =IF(LARGE($D$5:$D$1830,I6)>0,INDEX($A$5:$A$1830,MATCH(LARGE($D$5:$D$1830,I6),$D$5:$D$1830,0)),"-") -> North Indian | K6: =IF(LARGE($D$5:$D$1830,I6)>0,INDEX($B$5:$B$1830,MATCH(LARGE($D$5:$D$1830,I6),$D$5:$D$1830,0)),0) -> 46241
A7: Afghani, North Indian | B7: =SUMIFS(Data!$O$2:$O$9552,Data!$H$2:$H$9552,A7,Data!$V$2:$V$9552,1) -> 0 | C7: =COUNTIFS(Data!$H$2:$H$9552,A7,Data!$V$2:$V$9552,1) -> 1 | D7: =IF(C7>0,B7+ROW()/1000000,0) -> 7e-06 | F7: Agra | G7: =COUNTIFS(Data!$D$2:$D$9552,F7,Data!$V$2:$V$9552,1) -> 20 | I7: 3 | J7: =IF(LARGE($D$5:$D$1830,I7)>0,INDEX($A$5:$A$1830,MATCH(LARGE($D$5:$D$1830,I7),$D$5:$D$1830,0)),"-") -> North Indian, Chinese | K7: =IF(LARGE($D$5:$D$1830,I7)>0,INDEX($B$5:$B$1830,MATCH(LARGE($D$5:$D$1830,I7),$D$5:$D$1830,0)),0) -> 42012
A8: Afghani, North Indian, Pakistani, Arabian | B8: =SUMIFS(Data!$O$2:$O$9552,Data!$H$2:$H$9552,A8,Data!$V$2:$V$9552,1) -> 3 | C8: =COUNTIFS(Data!$H$2:$H$9552,A8,Data!$V$2:$V$9552,1) -> 1 | D8: =IF(C8>0,B8+ROW()/1000000,0) -> 3.000008 | F8: Ahmedabad | G8: =COUNTIFS(Data!$D$2:$D$9552,F8,Data!$V$2:$V$9552,1) -> 21 | I8: 4 | J8: =IF(LARGE($D$5:$D$1830,I8)>0,INDEX($A$5:$A$1830,MATCH(LARGE($D$5:$D$1830,I8),$D$5:$D$1830,0)),"-") -> Cafe | K8: =IF(LARGE($D$5:$D$1830,I8)>0,INDEX($B$5:$B$1830,MATCH(LARGE($D$5:$D$1830,I8),$D$5:$D$1830,0)),0) -> 30657
A9: African | B9: =SUMIFS(Data!$O$2:$O$9552,Data!$H$2:$H$9552,A9,Data!$V$2:$V$9552,1) -> 373 | C9: =COUNTIFS(Data!$H$2:$H$9552,A9,Data!$V$2:$V$9552,1) -> 1 | D9: =IF(C9>0,B9+ROW()/1000000,0) -> 373.00001 | F9: Albany | G9: =COUNTIFS(Data!$D$2:$D$9552,F9,Data!$V$2:$V$9552,1) -> 20 | I9: 5 | J9: =IF(LARGE($D$5:$D$1830,I9)>0,INDEX($A$5:$A$1830,MATCH(LARGE($D$5:$D$1830,I9),$D$5:$D$1830,0)),"-") -> Chinese | K9: =IF(LARGE($D$5:$D$1830,I9)>0,INDEX($B$5:$B$1830,MATCH(LARGE($D$5:$D$1830,I9),$D$5:$D$1830,0)),0) -> 21925
A10: African, Portuguese | B10: =SUMIFS(Data!$O$2:$O$9552,Data!$H$2:$H$9552,A10,Data!$V$2:$V$9552,1) -> 265 | C10: =COUNTIFS(Data!$H$2:$H$9552,A10,Data!$V$2:$V$9552,1) -> 1 | D10: =IF(C10>0,B10+ROW()/1000000,0) -> 265.00001 | F10: Allahabad | G10: =COUNTIFS(Data!$D$2:$D$9552,F10,Data!$V$2:$V$9552,1) -> 20
A11: American | B11: =SUMIFS(Data!$O$2:$O$9552,Data!$H$2:$H$9552,A11,Data!$V$2:$V$9552,1) -> 7802 | C11: =COUNTIFS(Data!$H$2:$H$9552,A11,Data!$V$2:$V$9552,1) -> 31 | D11: =IF(C11>0,B11+ROW()/1000000,0) -> 7802 | F11: Amritsar | G11: =COUNTIFS(Data!$D$2:$D$9552,F11,Data!$V$2:$V$9552,1) -> 21
A12: American, Asian, Burger | B12: =SUMIFS(Data!$O$2:$O$9552,Data!$H$2:$H$9552,A12,Data!$V$2:$V$9552,1) -> 1078 | C12: =COUNTIFS(Data!$H$2:$H$9552,A12,Data!$V$2:$V$9552,1) -> 1 | D12: =IF(C12>0,B12+ROW()/1000000,0) -> 1078 | F12: Ankara | G12: =COUNTIFS(Data!$D$2:$D$9552,F12,Data!$V$2:$V$9552,1) -> 20 | I12: Rank | J12: Top-5 Restaurants by Avg Cost for Two (USD) | K12: USD
A13: American, Asian, European, Seafood | B13: =SUMIFS(Data!$O$2:$O$9552,Data!$H$2:$H$9552,A13,Data!$V$2:$V$9552,1) -> 1691 | C13: =COUNTIFS(Data!$H$2:$H$9552,A13,Data!$V$2:$V$9552,1) -> 1 | D13: =IF(C13>0,B13+ROW()/1000000,0) -> 1691 | F13: Armidale | G13: =COUNTIFS(Data!$D$2:$D$9552,F13,Data!$V$2:$V$9552,1) -> 1 | I13: 1 | J13: =IF(LARGE(Data!$W$2:$W$9552,I13)>0,INDEX(Data!$B$2:$B$9552,MATCH(LARGE(Data!$W$2:$W$9552,I13),Data!$W$2:$W$9552,0)),"-") -> Spiral - Sofitel Philippine Plaza Manila | K13: =IF(LARGE(Data!$W$2:$W$9552,I13)>0,INDEX(Data!$T$2:$T$9552,MATCH(LARGE(Data!$W$2:$W$9552,I13),Data!$W$2:$W$9552,0)),0) -> 438
A14: American, Asian, Italian, Seafood | B14: =SUMIFS(Data!$O$2:$O$9552,Data!$H$2:$H$9552,A14,Data!$V$2:$V$9552,1) -> 618 | C14: =COUNTIFS(Data!$H$2:$H$9552,A14,Data!$V$2:$V$9552,1) -> 1 | D14: =IF(C14>0,B14+ROW()/1000000,0) -> 618.00001 | F14: Athens | G14: =COUNTIFS(Data!$D$2:$D$9552,F14,Data!$V$2:$V$9552,1) -> 20 | I14: 2 | J14: =IF(LARGE(Data!$W$2:$W$9552,I14)>0,INDEX(Data!$B$2:$B$9552,MATCH(LARGE(Data!$W$2:$W$9552,I14),Data!$W$2:$W$9552,0)),"-") -> Restaurant Andre | K14: =IF(LARGE(Data!$W$2:$W$9552,I14)>0,INDEX(Data!$T$2:$T$9552,MATCH(LARGE(Data!$W$2:$W$9552,I14),Data!$W$2:$W$9552,0)),0) -> 385
A15: American, Asian, North Indian, Mexican, South Indian | B15: =SUMIFS(Data!$O$2:$O$9552,Data!$H$2:$H$9552,A15,Data!$V$2:$V$9552,1) -> 21 | C15: =COUNTIFS(Data!$H$2:$H$9552,A15,Data!$V$2:$V$9552,1) -> 1 | D15: =IF(C15>0,B15+ROW()/1000000,0) -> 21.000015 | F15: Auckland | G15: =COUNTIFS(Data!$D$2:$D$9552,F15,Data!$V$2:$V$9552,1) -> 20 | I15: 3 | J15: =IF(LARGE(Data!$W$2:$W$9552,I15)>0,INDEX(Data!$B$2:$B$9552,MATCH(LARGE(Data!$W$2:$W$9552,I15),Data!$W$2:$W$9552,0)),"-") -> Jaan | K15: =IF(LARGE(Data!$W$2:$W$9552,I15)>0,INDEX(Data!$T$2:$T$9552,MATCH(LARGE(Data!$W$2:$W$9552,I15),Data!$W$2:$W$9552,0)),0) -> 331.1
A16: American, BBQ | B16: =SUMIFS(Data!$O$2:$O$9552,Data!$H$2:$H$9552,A16,Data!$V$2:$V$9552,1) -> 724 | C16: =COUNTIFS(Data!$H$2:$H$9552,A16,Data!$V$2:$V$9552,1) -> 2 | D16: =IF(C16>0,B16+ROW()/1000000,0) -> 724.00002 | F16: Augusta | G16: =COUNTIFS(Data!$D$2:$D$9552,F16,Data!$V$2:$V$9552,1) -> 20 | I16: 4 | J16: =IF(LARGE(Data!$W$2:$W$9552,I16)>0,INDEX(Data!$B$2:$B$9552,MATCH(LARGE(Data!$W$2:$W$9552,I16),Data!$W$2:$W$9552,0)),"-") -> Restaurant Gordon Ramsay | K16: =IF(LARGE(Data!$W$2:$W$9552,I16)>0,INDEX(Data!$T$2:$T$9552,MATCH(LARGE(Data!$W$2:$W$9552,I16),Data!$W$2:$W$9552,0)),0) -> 299
A17: American, BBQ, Burger | B17: =SUMIFS(Data!$O$2:$O$9552,Data!$H$2:$H$9552,A17,Data!$V$2:$V$9552,1) -> 439 | C17: =COUNTIFS(Data!$H$2:$H$9552,A17,Data!$V$2:$V$9552,1) -> 2 | D17: =IF(C17>0,B17+ROW()/1000000,0) -> 439.00002 | F17: Aurangabad | G17: =COUNTIFS(Data!$D$2:$D$9552,F17,Data!$V$2:$V$9552,1) -> 20 | I17: 5 | J17: =IF(LARGE(Data!$W$2:$W$9552,I17)>0,INDEX(Data!$B$2:$B$9552,MATCH(LARGE(Data!$W$2:$W$9552,I17),Data!$W$2:$W$9552,0)),"-") -> Heat - Edsa Shangri-La | K17: =IF(LARGE(Data!$W$2:$W$9552,I17)>0,INDEX(Data!$T$2:$T$9552,MATCH(LARGE(Data!$W$2:$W$9552,I17),Data!$W$2:$W$9552,0)),0) -> 292
A18: American, BBQ, Sandwich | B18: =SUMIFS(Data!$O$2:$O$9552,Data!$H$2:$H$9552,A18,Data!$V$2:$V$9552,1) -> 1252 | C18: =COUNTIFS(Data!$H$2:$H$9552,A18,Data!$V$2:$V$9552,1) -> 1 | D18: =IF(C18>0,B18+ROW()/1000000,0) -> 1252 | F18: Balingup | G18: =COUNTIFS(Data!$D$2:$D$9552,F18,Data!$V$2:$V$9552,1) -> 1
A19: American, BBQ, Seafood | B19: =SUMIFS(Data!$O$2:$O$9552,Data!$H$2:$H$9552,A19,Data!$V$2:$V$9552,1) -> 65 | C19: =COUNTIFS(Data!$H$2:$H$9552,A19,Data!$V$2:$V$9552,1) -> 1 | D19: =IF(C19>0,B19+ROW()/1000000,0) -> 65.000019 | F19: Bandung | G19: =COUNTIFS(Data!$D$2:$D$9552,F19,Data!$V$2:$V$9552,1) -> 1
A20: American, BBQ, Southern | B20: =SUMIFS(Data!$O$2:$O$9552,Data!$H$2:$H$9552,A20,Data!$V$2:$V$9552,1) -> 150 | C20: =COUNTIFS(Data!$H$2:$H$9552,A20,Data!$V$2:$V$9552,1) -> 2 | D20: =IF(C20>0,B20+ROW()/1000000,0) -> 150.00002 | F20: Bangalore | G20: =COUNTIFS(Data!$D$2:$D$9552,F20,Data!$V$2:$V$9552,1) -> 20 | J20: Table booking | K20: Restaurants
A21: American, BBQ, Steak | B21: =SUMIFS(Data!$O$2:$O$9552,Data!$H$2:$H$9552,A21,Data!$V$2:$V$9552,1) -> 742 | C21: =COUNTIFS(Data!$H$2:$H$9552,A21,Data!$V$2:$V$9552,1) -> 4 | D21: =IF(C21>0,B21+ROW()/1000000,0) -> 742.00002 | F21: Beechworth | G21: =COUNTIFS(Data!$D$2:$D$9552,F21,Data!$V$2:$V$9552,1) -> 1 | J21: No | K21: =COUNTIFS(Data!$J$2:$J$9552,J21,Data!$V$2:$V$9552,1) -> 8393
A22: American, Bakery, European, Burger, Fusion | B22: =SUMIFS(Data!$O$2:$O$9552,Data!$H$2:$H$9552,A22,Data!$V$2:$V$9552,1) -> 28 | C22: =COUNTIFS(Data!$H$2:$H$9552,A22,Data!$V$2:$V$9552,1) -> 1 | D22: =IF(C22>0,B22+ROW()/1000000,0) -> 28.000022 | F22: Bhopal | G22: =COUNTIFS(Data!$D$2:$D$9552,F22,Data!$V$2:$V$9552,1) -> 20 | J22: Yes | K22: =COUNTIFS(Data!$J$2:$J$9552,J22,Data!$V$2:$V$9552,1) -> 1158
A23: American, Bar Food | B23: =SUMIFS(Data!$O$2:$O$9552,Data!$H$2:$H$9552,A23,Data!$V$2:$V$9552,1) -> 2225 | C23: =COUNTIFS(Data!$H$2:$H$9552,A23,Data!$V$2:$V$9552,1) -> 4 | D23: =IF(C23>0,B23+ROW()/1000000,0) -> 2225 | F23: Bhubaneshwar | G23: =COUNTIFS(Data!$D$2:$D$9552,F23,Data!$V$2:$V$9552,1) -> 21
A24: American, Bar Food, BBQ | B24: =SUMIFS(Data!$O$2:$O$9552,Data!$H$2:$H$9552,A24,Data!$V$2:$V$9552,1) -> 2 | C24: =COUNTIFS(Data!$H$2:$H$9552,A24,Data!$V$2:$V$9552,1) -> 1 | D24: =IF(C24>0,B24+ROW()/1000000,0) -> 2.000024 | F24: Birmingham | G24: =COUNTIFS(Data!$D$2:$D$9552,F24,Data!$V$2:$V$9552,1) -> 20 | J24: Online delivery | K24: Restaurants
A25: American, Bar Food, Sandwich | B25: =SUMIFS(Data!$O$2:$O$9552,Data!$H$2:$H$9552,A25,Data!$V$2:$V$9552,1) -> 747 | C25: =COUNTIFS(Data!$H$2:$H$9552,A25,Data!$V$2:$V$9552,1) -> 1 | D25: =IF(C25>0,B25+ROW()/1000000,0) -> 747.00003 | F25: Bogor | G25: =COUNTIFS(Data!$D$2:$D$9552,F25,Data!$V$2:$V$9552,1) -> 2 | J25: No | K25: =COUNTIFS(Data!$K$2:$K$9552,J25,Data!$V$2:$V$9552,1) -> 7100
A26: American, Breakfast | B26: =SUMIFS(Data!$O$2:$O$9552,Data!$H$2:$H$9552,A26,Data!$V$2:$V$9552,1) -> 1815 | C26: =COUNTIFS(Data!$H$2:$H$9552,A26,Data!$V$2:$V$9552,1) -> 7 | D26: =IF(C26>0,B26+ROW()/1000000,0) -> 1815 | F26: Boise | G26: =COUNTIFS(Data!$D$2:$D$9552,F26,Data!$V$2:$V$9552,1) -> 20 | J26: Yes | K26: =COUNTIFS(Data!$K$2:$K$9552,J26,Data!$V$2:$V$9552,1) -> 2451
A27: American, Breakfast, Burger | B27: =SUMIFS(Data!$O$2:$O$9552,Data!$H$2:$H$9552,A27,Data!$V$2:$V$9552,1) -> 977 | C27: =COUNTIFS(Data!$H$2:$H$9552,A27,Data!$V$2:$V$9552,1) -> 3 | D27: =IF(C27>0,B27+ROW()/1000000,0) -> 977.00003 | F27: Bras?lia | G27: =COUNTIFS(Data!$D$2:$D$9552,F27,Data!$V$2:$V$9552,1) -> 20
A28: American, Breakfast, Desserts | B28: =SUMIFS(Data!$O$2:$O$9552,Data!$H$2:$H$9552,A28,Data!$V$2:$V$9552,1) -> 96 | C28: =COUNTIFS(Data!$H$2:$H$9552,A28,Data!$V$2:$V$9552,1) -> 1 | D28: =IF(C28>0,B28+ROW()/1000000,0) -> 96.000028 | F28: Cape Town | G28: =COUNTIFS(Data!$D$2:$D$9552,F28,Data!$V$2:$V$9552,1) -> 20 | I28: Band # | J28: Avg Cost for Two (USD) | K28: Restaurants
A29: American, Breakfast, Diner | B29: =SUMIFS(Data!$O$2:$O$9552,Data!$H$2:$H$9552,A29,Data!$V$2:$V$9552,1) -> 20 | C29: =COUNTIFS(Data!$H$2:$H$9552,A29,Data!$V$2:$V$9552,1) -> 1 | D29: =IF(C29>0,B29+ROW()/1000000,0) -> 20.000029 | F29: Cedar Rapids/Iowa City | G29: =COUNTIFS(Data!$D$2:$D$9552,F29,Data!$V$2:$V$9552,1) -> 20 | I29: 1 | J29: <=10$ | K29: =COUNTIFS(Data!$U$2:$U$9552,I29,Data!$V$2:$V$9552,1) -> 7280
A30: American, Breakfast, Greek | B30: =SUMIFS(Data!$O$2:$O$9552,Data!$H$2:$H$9552,A30,Data!$V$2:$V$9552,1) -> 85 | C30: =COUNTIFS(Data!$H$2:$H$9552,A30,Data!$V$2:$V$9552,1) -> 1 | D30: =IF(C30>0,B30+ROW()/1000000,0) -> 85.00003 | F30: Chandigarh | G30: =COUNTIFS(Data!$D$2:$D$9552,F30,Data!$V$2:$V$9552,1) -> 18 | I30: 2 | J30: 11$-20$ | K30: =COUNTIFS(Data!$U$2:$U$9552,I30,Data!$V$2:$V$9552,1) -> 1247
A31: American, Breakfast, Hawaiian | B31: =SUMIFS(Data!$O$2:$O$9552,Data!$H$2:$H$9552,A31,Data!$V$2:$V$9552,1) -> 694 | C31: =COUNTIFS(Data!$H$2:$H$9552,A31,Data!$V$2:$V$9552,1) -> 1 | D31: =IF(C31>0,B31+ROW()/1000000,0) -> 694.00003 | F31: Chatham-Kent | G31: =COUNTIFS(Data!$D$2:$D$9552,F31,Data!$V$2:$V$9552,1) -> 1 | I31: 3 | J31: 21$-30$ | K31: =COUNTIFS(Data!$U$2:$U$9552,I31,Data!$V$2:$V$9552,1) -> 563
A32: American, Breakfast, Vegetarian | B32: =SUMIFS(Data!$O$2:$O$9552,Data!$H$2:$H$9552,A32,Data!$V$2:$V$9552,1) -> 797 | C32: =COUNTIFS(Data!$H$2:$H$9552,A32,Data!$V$2:$V$9552,1) -> 1 | D32: =IF(C32>0,B32+ROW()/1000000,0) -> 797.00003 | F32: Chennai | G32: =COUNTIFS(Data!$D$2:$D$9552,F32,Data!$V$2:$V$9552,1) -> 20 | I32: 4 | J32: 31$-40$ | K32: =COUNTIFS(Data!$U$2:$U$9552,I32,Data!$V$2:$V$9552,1) -> 201
A33: American, British, Continental | B33: =SUMIFS(Data!$O$2:$O$9552,Data!$H$2:$H$9552,A33,Data!$V$2:$V$9552,1) -> 969 | C33: =COUNTIFS(Data!$H$2:$H$9552,A33,Data!$V$2:$V$9552,1) -> 1 | D33: =IF(C33>0,B33+ROW()/1000000,0) -> 969.00003 | F33: Clatskanie | G33: =COUNTIFS(Data!$D$2:$D$9552,F33,Data!$V$2:$V$9552,1) -> 1 | I33: 5 | J33: 41$-50$ | K33: =COUNTIFS(Data!$U$2:$U$9552,I33,Data!$V$2:$V$9552,1) -> 76
A34: American, Burger | B34: =SUMIFS(Data!$O$2:$O$9552,Data!$H$2:$H$9552,A34,Data!$V$2:$V$9552,1) -> 6371 | C34: =COUNTIFS(Data!$H$2:$H$9552,A34,Data!$V$2:$V$9552,1) -> 13 | D34: =IF(C34>0,B34+ROW()/1000000,0) -> 6371 | F34: Cochrane | G34: =COUNTIFS(Data!$D$2:$D$9552,F34,Data!$V$2:$V$9552,1) -> 1 | I34: 6 | J34: 51$-100$ | K34: =COUNTIFS(Data!$U$2:$U$9552,I34,Data!$V$2:$V$9552,1) -> 145
A35: American, Burger, Cafe | B35: =SUMIFS(Data!$O$2:$O$9552,Data!$H$2:$H$9552,A35,Data!$V$2:$V$9552,1) -> 9667 | C35: =COUNTIFS(Data!$H$2:$H$9552,A35,Data!$V$2:$V$9552,1) -> 1 | D35: =IF(C35>0,B35+ROW()/1000000,0) -> 9667 | F35: Coimbatore | G35: =COUNTIFS(Data!$D$2:$D$9552,F35,Data!$V$2:$V$9552,1) -> 20 | I35: 7 | J35: 101$-250$ | K35: =COUNTIFS(Data!$U$2:$U$9552,I35,Data!$V$2:$V$9552,1) -> 34
A36: American, Burger, Cajun | B36: =SUMIFS(Data!$O$2:$O$9552,Data!$H$2:$H$9552,A36,Data!$V$2:$V$9552,1) -> 88 | C36: =COUNTIFS(Data!$H$2:$H$9552,A36,Data!$V$2:$V$9552,1) -> 1 | D36: =IF(C36>0,B36+ROW()/1000000,0) -> 88.000036 | F36: Colombo | G36: =COUNTIFS(Data!$D$2:$D$9552,F36,Data!$V$2:$V$9552,1) -> 20 | I36: 8 | J36: >250$ | K36: =COUNTIFS(Data!$U$2:$U$9552,I36,Data!$V$2:$V$9552,1) -> 5
A37: American, Burger, Fast Food | B37: =SUMIFS(Data!$O$2:$O$9552,Data!$H$2:$H$9552,A37,Data!$V$2:$V$9552,1) -> 413 | C37: =COUNTIFS(Data!$H$2:$H$9552,A37,Data!$V$2:$V$9552,1) -> 1 | D37: =IF(C37>0,B37+ROW()/1000000,0) -> 413.00004 | F37: Columbus | G37: =COUNTIFS(Data!$D$2:$D$9552,F37,Data!$V$2:$V$9552,1) -> 20
A38: American, Burger, Grill | B38: =SUMIFS(Data!$O$2:$O$9552,Data!$H$2:$H$9552,A38,Data!$V$2:$V$9552,1) -> 162 | C38: =COUNTIFS(Data!$H$2:$H$9552,A38,Data!$V$2:$V$9552,1) -> 1 | D38: =IF(C38>0,B38+ROW()/1000000,0) -> 162.00004 | F38: Consort | G38: =COUNTIFS(Data!$D$2:$D$9552,F38,Data!$V$2:$V$9552,1) -> 1
A39: American, Burger, Pizza, Cafe | B39: =SUMIFS(Data!$O$2:$O$9552,Data!$H$2:$H$9552,A39,Data!$V$2:$V$9552,1) -> 89 | C39: =COUNTIFS(Data!$H$2:$H$9552,A39,Data!$V$2:$V$9552,1) -> 1 | D39: =IF(C39>0,B39+ROW()/1000000,0) -> 89.000039 | F39: Dalton | G39: =COUNTIFS(Data!$D$2:$D$9552,F39,Data!$V$2:$V$9552,1) -> 20 | I39: Low | J39: Rating band | K39: Restaurants | L39: High
A40: American, Burger, Sandwich | B40: =SUMIFS(Data!$O$2:$O$9552,Data!$H$2:$H$9552,A40,Data!$V$2:$V$9552,1) -> 1104 | C40: =COUNTIFS(Data!$H$2:$H$9552,A40,Data!$V$2:$V$9552,1) -> 4 | D40: =IF(C40>0,B40+ROW()/1000000,0) -> 1104 | F40: Davenport | G40: =COUNTIFS(Data!$D$2:$D$9552,F40,Data!$V$2:$V$9552,1) -> 20 | I40: 1 | J40: 1.0 (unrated) | K40: =COUNTIFS(Data!$Q$2:$Q$9552,">="&I40,Data!$Q$2:$Q$9552,"<="&L40,Data!$V$2:$V$9552,1) -> 2148 | L40: 1
A41: American, Cafe | B41: =SUMIFS(Data!$O$2:$O$9552,Data!$H$2:$H$9552,A41,Data!$V$2:$V$9552,1) -> 676 | C41: =COUNTIFS(Data!$H$2:$H$9552,A41,Data!$V$2:$V$9552,1) -> 1 | D41: =IF(C41>0,B41+ROW()/1000000,0) -> 676.00004 | F41: Dehradun | G41: =COUNTIFS(Data!$D$2:$D$9552,F41,Data!$V$2:$V$9552,1) -> 20 | I41: 1.1 | J41: 1.1-2.5 | K41: =COUNTIFS(Data!$Q$2:$Q$9552,">="&I41,Data!$Q$2:$Q$9552,"<="&L41,Data!$V$2:$V$9552,1) -> 296 | L41: 2.5
...

Sheet Lookup
A1: Country & currency conversion (editable)
A2: Rates are APPROXIMATE USD per 1 unit of local currency (assumption by the author, not from the dataset). Edit column D to update everything.
A3: CountryCode | B3: Country | C3: Currency | D3: USD per 1 unit | F3: Country dropdown list
A4: 1 | B4: India | C4: INR | D4: 0.012 | F4: All
A5: 14 | B5: Australia | C5: AUD | D5: 0.65 | F5: =B4 -> India
A6: 30 | B6: Brazil | C6: BRL | D6: 0.18 | F6: =B5 -> Australia
A7: 37 | B7: Canada | C7: CAD | D7: 0.72 | F7: =B6 -> Brazil
A8: 94 | B8: Indonesia | C8: IDR | D8: 6e-05 | F8: =B7 -> Canada
A9: 148 | B9: New Zealand | C9: NZD | D9: 0.59 | F9: =B8 -> Indonesia
A10: 162 | B10: Philippines | C10: BWP (dataset: Botswana Pula) | D10: 0.073 | F10: =B9 -> New Zealand
A11: 166 | B11: Qatar | C11: QAR | D11: 0.275 | F11: =B10 -> Philippines
A12: 184 | B12: Singapore | C12: SGD | D12: 0.77 | F12: =B11 -> Qatar
A13: 189 | B13: South Africa | C13: ZAR | D13: 0.055 | F13: =B12 -> Singapore
A14: 191 | B14: Sri Lanka | C14: LKR | D14: 0.0033 | F14: =B13 -> South Africa
A15: 208 | B15: Turkey | C15: TRY | D15: 0.023 | F15: =B14 -> Sri Lanka
A16: 214 | B16: UAE | C16: AED | D16: 0.272 | F16: =B15 -> Turkey
... A18: 216 | B18: United States | C18: USD | D18: 1 | F18: =B17 -> United Kingdom
F19: =B18 -> United States
A20: Country names follow the standard Zomato country-code list. Philippines (162) is labelled Botswana Pula in the dataset currency column; kept as given.
